Workbook

Sheet XLOOKUP
A1: XLOOKUP
A3: Syntax is XLOOKUP(lookup_value, lookup_array, return_array, [if_not_found], [match_mode], [search_mode])
A6: Employee | B6: Employee ID | C6: Sales
A7: MANPREET SINGH | B7: =_xlfn.XLOOKUP(XLOOKUP!A7,DATA!$C$2:$C$21,DATA!$A$2:$A$21,"Not Applicable",0,1) -> ID46 | C7: =_xlfn.XLOOKUP(A7,DATA!$C$2:$C$21,DATA!$D$2:$D$21,"not found",0,1) -> 46000
A8: JASLEEN KAUR | B8: =_xlfn.XLOOKUP(XLOOKUP!A8,DATA!$C$2:$C$21,DATA!$A$2:$A$21,"Not Applicable",0,1) -> ID85 | C8: =_xlfn.XLOOKUP(A8,DATA!$C$2:$C$21,DATA!$D$2:$D$21,"not found",0,1) -> 23000
A9: KARAN VERMA | B9: =_xlfn.XLOOKUP(XLOOKUP!A9,DATA!$C$2:$C$21,DATA!$A$2:$A$21,"Not Applicable",0,1) -> ID12 | C9: =_xlfn.XLOOKUP(A9,DATA!$C$2:$C$21,DATA!$D$2:$D$21,"not found",0,1) -> 21500
A10: NAVDEEP SINGH | B10: =_xlfn.XLOOKUP(XLOOKUP!A10,DATA!$C$2:$C$21,DATA!$A$2:$A$21,"Not Applicable",0,1) -> ID45 | C10: =_xlfn.XLOOKUP(A10,DATA!$C$2:$C$21,DATA!$D$2:$D$21,"not found",0,1) -> 852000
A11: RAJVEER SINGH | B11: =_xlfn.XLOOKUP(XLOOKUP!A11,DATA!$C$2:$C$21,DATA!$A$2:$A$21,"Not Applicable",0,1) -> IUD35 | C11: =_xlfn.XLOOKUP(A11,DATA!$C$2:$C$21,DATA!$D$2:$D$21,"not found",0,1) -> 75200
A12: KOMAL SHARMA | B12: =_xlfn.XLOOKUP(XLOOKUP!A12,DATA!$C$2:$C$21,DATA!$A$2:$A$21,"Not Applicable",0,1) -> ID25 | C12: =_xlfn.XLOOKUP(A12,DATA!$C$2:$C$21,DATA!$D$2:$D$21,"not found",0,1) -> 9560
A13: AMANDEEP KAUR | B13: =_xlfn.XLOOKUP(XLOOKUP!A13,DATA!$C$2:$C$21,DATA!$A$2:$A$21,"Not Applicable",0,1) -> ID16 | C13: =_xlfn.XLOOKUP(A13,DATA!$C$2:$C$21,DATA!$D$2:$D$21,"not found",0,1) -> 75200
A14: SUKHMAN SINGH | B14: =_xlfn.XLOOKUP(XLOOKUP!A14,DATA!$C$2:$C$21,DATA!$A$2:$A$21,"Not Applicable",0,1) -> ID88 | C14: =_xlfn.XLOOKUP(A14,DATA!$C$2:$C$21,DATA!$D$2:$D$21,"not found",0,1) -> 56000
A15: SIMRAN KAUR | B15: =_xlfn.XLOOKUP(XLOOKUP!A15,DATA!$C$2:$C$21,DATA!$A$2:$A$21,"Not Applicable",0,1) -> ID8 | C15: =_xlfn.XLOOKUP(A15,DATA!$C$2:$C$21,DATA!$D$2:$D$21,"not found",0,1) -> 45200
A16: HARPREET SINGH | B16: =_xlfn.XLOOKUP(XLOOKUP!A16,DATA!$C$2:$C$21,DATA!$A$2:$A$21,"Not Applicable",0,1) -> ID5 | C16: =_xlfn.XLOOKUP(A16,DATA!$C$2:$C$21,DATA!$D$2:$D$21,"not found",0,1) -> 852000
A17: GURLEEN KAUR | B17: =_xlfn.XLOOKUP(XLOOKUP!A17,DATA!$C$2:$C$21,DATA!$A$2:$A$21,"Not Applicable",0,1) -> ID15 | C17: =_xlfn.XLOOKUP(A17,DATA!$C$2:$C$21,DATA!$D$2:$D$21,"not found",0,1) -> 95000
A18: abc | B18: =_xlfn.XLOOKUP(XLOOKUP!A18,DATA!$C$2:$C$21,DATA!$A$2:$A$21,"Not Applicable",0,1) -> Not Applicable | C18: =_xlfn.XLOOKUP(A18,DATA!$C$2:$C$21,DATA!$D$2:$D$21,"not found",0,1) -> not found

Sheet DATA
A2: Employee ID | B2: Departments | C2: Employee | D2: Sales
A3: ID18 | B3: Sales | C3: AMAN SHARMA | D3: 56200
A4: ID8 | B4: Marketing | C4: SIMRAN KAUR | D4: 45200
A5: ID5 | B5: HR | C5: HARPREET SINGH | D5: 852000
A6: ID15 | B6: Production | C6: GURLEEN KAUR | D6: 95000
A7: ID46 | B7: Loan | C7: MANPREET SINGH | D7: 46000
A8: ID85 | B8: Sales | C8: JASLEEN KAUR | D8: 23000
A9: ID12 | B9: Marketing | C9: KARAN VERMA | D9: 21500
A10: ID45 | B10: HR | C10: NAVDEEP SINGH | D10: 852000
A11: IUD35 | B11: Production | C11: RAJVEER SINGH | D11: 75200
A12: ID25 | B12: Loan | C12: KOMAL SHARMA | D12: 9560
A13: ID16 | B13: HR | C13: AMANDEEP KAUR | D13: 75200
A14: ID88 | B14: Production | C14: SUKHMAN SINGH | D14: 56000
... A21: ID71 | B21: Production | C21: LOVEPREET SINGH | D21: 69000

Sheet XLOOKUP ASSIGNMENT
A1: EMP ID | B1: EMPLOYEE NAME | C1: DEPARTMENT | D1: DESIGNATION | E1: CITY | F1: SALARY
A2: E101 | B2: AMAN | C2: HR | D2: MANAGER | E2: DELHI | F2: 55000 | H2: EMP ID | I2: DEPARTMENT | J2: CITY | L2: EMP NAME | M2: SALARY | N2: DESIGNATION
A3: E102 | B3: SIMRAN | C3: SALES | D3: EXECUTIVE | E3: CHANDIGARH | F3: 42000 | H3: E101 | I3: {=_xlfn.XLOOKUP(H3,Table1[[#All],[EMP ID]],Table1[[#All],[DEPARTMENT]],"NOT FOUND",0,1)} -> HR | J3: {=_xlfn.XLOOKUP(H3,Table1[[#All],[EMP ID]],Table1[[#All],[CITY]],"NOT AVAILABLE",0,1)} -> DELHI | L3: AMAN | M3: {=_xlfn.XLOOKUP(L3,Table1[[#All],[EMPLOYEE NAME]],Table1[[#All],[SALARY]],"NOT FOUND",0,1)} -> 55000 | N3: {=_xlfn.XLOOKUP(L3,Table1[[#All],[EMPLOYEE NAME]],Table1[[#All],[DESIGNATION]],"NOT FOUND",0,1)} -> MANAGER
A4: E103 | B4: RAHUL | C4: IT | D4: DEVELOPER | E4: AMRITSAR | F4: 60000 | H4: E102 | I4: {=_xlfn.XLOOKUP(H4,Table1[[#All],[EMP ID]],Table1[[#All],[DEPARTMENT]],"NOT FOUND",0,1)} -> SALES | J4: {=_xlfn.XLOOKUP(H4,Table1[[#All],[EMP ID]],Table1[[#All],[CITY]],"NOT FOUND",0,1)} -> CHANDIGARH | L4: SIMRAN | M4: {=_xlfn.XLOOKUP(L4,Table1[[#All],[EMPLOYEE NAME]],Table1[[#All],[SALARY]],"NOT FOUND",0,1)} -> 42000 | N4: {=_xlfn.XLOOKUP(L4,Table1[[#All],[EMPLOYEE NAME]],Table1[[#All],[DESIGNATION]],"NOT FOUND",0,1)} -> EXECUTIVE
A5: E104 | B5: PRIYA | C5: FINANCE | D5: ACCOUNTANT | E5: LUDHIANA | F5: 48000 | H5: E103 | I5: {=_xlfn.XLOOKUP(H5,Table1[[#All],[EMP ID]],Table1[[#All],[DEPARTMENT]],"NOT FOUND",0,1)} -> IT | J5: {=_xlfn.XLOOKUP(H5,Table1[[#All],[EMP ID]],Table1[[#All],[CITY]],"NOT FOUND",0,1)} -> AMRITSAR | L5: RAHUL | M5: {=_xlfn.XLOOKUP(L5,Table1[[#All],[EMPLOYEE NAME]],Table1[[#All],[SALARY]],"NOT FOUND",0,1)} -> 60000 | N5: {=_xlfn.XLOOKUP(L5,Table1[[#All],[EMPLOYEE NAME]],Table1[[#All],[DESIGNATION]],"NOT FOUND",0,1)} -> DEVELOPER
A6: E105 | B6: KARAN | C6: MARKETING | D6: OFFICER | E6: PATIALA | F6: 45000 | H6: E104 | I6: {=_xlfn.XLOOKUP(H6,Table1[[#All],[EMP ID]],Table1[[#All],[DEPARTMENT]],"NOT FOUND",0,1)} -> FINANCE | J6: {=_xlfn.XLOOKUP(H6,Table1[[#All],[EMP ID]],Table1[[#All],[CITY]],"NOT FOUND",0,1)} -> LUDHIANA | L6: PRIYA | M6: {=_xlfn.XLOOKUP(L6,Table1[[#All],[EMPLOYEE NAME]],Table1[[#All],[SALARY]],"NOT FOUND",0,1)} -> 48000 | N6: {=_xlfn.XLOOKUP(L6,Table1[[#All],[EMPLOYEE NAME]],Table1[[#All],[DESIGNATION]],"NOT FOUND",0,1)} -> ACCOUNTANT
A7: E106 | B7: NEHA | C7: IT | D7: ANALYST | E7: JALANDHAR | F7: 52000 | H7: E105 | I7: {=_xlfn.XLOOKUP(H7,Table1[[#All],[EMP ID]],Table1[[#All],[DEPARTMENT]],"NOT FOUND",0,1)} -> MARKETING | J7: {=_xlfn.XLOOKUP(H7,Table1[[#All],[EMP ID]],Table1[[#All],[CITY]],"NOT FOUND",0,1)} -> PATIALA | L7: KARAN | M7: {=_xlfn.XLOOKUP(L7,Table1[[#All],[EMPLOYEE NAME]],Table1[[#All],[SALARY]],"NOT FOUND",0,1)} -> 45000 | N7: {=_xlfn.XLOOKUP(L7,Table1[[#All],[EMPLOYEE NAME]],Table1[[#All],[DESIGNATION]],"NOT FOUND",0,1)} -> OFFICER
A8: E107 | B8: ARJUN | C8: HR | D8: ASSISTANT | E8: MOHALI | F8: 35000 | H8: E106 | I8: {=_xlfn.XLOOKUP(H8,Table1[[#All],[EMP ID]],Table1[[#All],[DEPARTMENT]],"NOT FOUND",0,1)} -> IT | J8: {=_xlfn.XLOOKUP(H8,Table1[[#All],[EMP ID]],Table1[[#All],[CITY]],"NOT FOUND",0,1)} -> JALANDHAR | L8: NEHA | M8: {=_xlfn.XLOOKUP(L8,Table1[[#All],[EMPLOYEE NAME]],Table1[[#All],[SALARY]],"NOT FOUND",0,1)} -> 52000 | N8: {=_xlfn.XLOOKUP(L8,Table1[[#All],[EMPLOYEE NAME]],Table1[[#All],[DESIGNATION]],"NOT FOUND",0,1)} -> ANALYST
A9: E108 | B9: MEENA | C9: SALES | D9: MANAGER | E9: DELHI | F9: 65000 | H9: E107 | I9: {=_xlfn.XLOOKUP(H9,Table1[[#All],[EMP ID]],Table1[[#All],[DEPARTMENT]],"NOT FOUND",0,1)} -> HR | J9: {=_xlfn.XLOOKUP(H9,Table1[[#All],[EMP ID]],Table1[[#All],[CITY]],"NOT FOUND",0,1)} -> MOHALI | L9: ARJUN | M9: {=_xlfn.XLOOKUP(L9,Table1[[#All],[EMPLOYEE NAME]],Table1[[#All],[SALARY]],"NOT FOUND",0,1)} -> 35000 | N9: {=_xlfn.XLOOKUP(L9,Table1[[#All],[EMPLOYEE NAME]],Table1[[#All],[DESIGNATION]],"NOT FOUND",0,1)} -> ASSISTANT
A10: E109 | B10: ROHIT | C10: FINANCE | D10: EXECUTIVE | E10: AMBALA | F10: 41000 | H10: E108 | I10: {=_xlfn.XLOOKUP(H10,Table1[[#All],[EMP ID]],Table1[[#All],[DEPARTMENT]],"NOT FOUND",0,1)} -> SALES | J10: {=_xlfn.XLOOKUP(H10,Table1[[#All],[EMP ID]],Table1[[#All],[CITY]],"NOT FOUND",0,1)} -> DELHI | L10: MEENA | M10: {=_xlfn.XLOOKUP(L10,Table1[[#All],[EMPLOYEE NAME]],Table1[[#All],[SALARY]],"NOT FOUND",0,1)} -> 65000 | N10: {=_xlfn.XLOOKUP(L10,Table1[[#All],[EMPLOYEE NAME]],Table1[[#All],[DESIGNATION]],"NOT FOUND",0,1)} -> MANAGER
A11: E110 | B11: POOJA | C11: MARKETING | D11: COORDINATOR | E11: BATHINDA | F11: 39000 | H11: E109 | I11: {=_xlfn.XLOOKUP(H11,Table1[[#All],[EMP ID]],Table1[[#All],[DEPARTMENT]],"NOT FOUND",0,1)} -> FINANCE | J11: {=_xlfn.XLOOKUP(H11,Table1[[#All],[EMP ID]],Table1[[#All],[CITY]],"NOT FOUND",0,1)} -> AMBALA | L11: ROHIT | M11: {=_xlfn.XLOOKUP(L11,Table1[[#All],[EMPLOYEE NAME]],Table1[[#All],[SALARY]],"NOT FOUND",0,1)} -> 41000 | N11: {=_xlfn.XLOOKUP(L11,Table1[[#All],[EMPLOYEE NAME]],Table1[[#All],[DESIGNATION]],"NOT FOUND",0,1)} -> EXECUTIVE
A12: E12 | B12: RAHUL | C12: SALES | D12: ANALYST | E12: CHANDIGARH | F12: 72000 | H12: E110 | I12: {=_xlfn.XLOOKUP(H12,Table1[[#All],[EMP ID]],Table1[[#All],[DEPARTMENT]],"NOT FOUND",0,1)} -> MARKETING | J12: {=_xlfn.XLOOKUP(H12,Table1[[#All],[EMP ID]],Table1[[#All],[CITY]],"NOT FOUND",0,1)} -> BATHINDA | L12: POOJA | M12: {=_xlfn.XLOOKUP(L12,Table1[[#All],[EMPLOYEE NAME]],Table1[[#All],[SALARY]],"NOT FOUND",0,1)} -> 39000 | N12: {=_xlfn.XLOOKUP(L12,Table1[[#All],[EMPLOYEE NAME]],Table1[[#All],[DESIGNATION]],"NOT FOUND",0,1)} -> COORDINATOR
H13: E111 | I13: {=_xlfn.XLOOKUP(H13,Table1[[#All],[EMP ID]],Table1[[#All],[DEPARTMENT]],"NOT FOUND",0,1)} -> NOT FOUND | J13: {=_xlfn.XLOOKUP(H13,Table1[[#All],[EMP ID]],Table1[[#All],[CITY]],"NOT FOUND",0,1)} -> NOT FOUND | L13: SIYA | M13: {=_xlfn.XLOOKUP(L13,Table1[[#All],[EMPLOYEE NAME]],Table1[[#All],[SALARY]],"NOT FOUND",0,1)} -> NOT FOUND | N13: {=_xlfn.XLOOKUP(L13,Table1[[#All],[EMPLOYEE NAME]],Table1[[#All],[DESIGNATION]],"NOT FOUND",0,1)} -> NOT FOUND
L15: RAHUL | M15: {=_xlfn.XLOOKUP(L15,Table1[[#All],[EMPLOYEE NAME]],Table1[[#All],[SALARY]],"NOT FOUND",0,-1)} -> 72000 | N15: {=_xlfn.XLOOKUP(L15,Table1[[#All],[EMPLOYEE NAME]],Table1[[#All],[DESIGNATION]],"NOT FOUND",0,-1)} -> ANALYST
A20: #MIX ASSIGNMENT
A22: EMP ID | B22: EMP NAME | C22: DEPARTMENT | D22: BASIC SALARY | E22: HRA | F22: BONUS | G22: EXPERIENCE | H22: CITY | K22: DEPARTMENT
A23: E101 | B23: AMAN | C23: MANAGER | D23: 45000 | E23: 5000 | F23: 3000 | G23: 8 | H23: DELHI | J23: E105 | K23: =VLOOKUP(J23,A22:H30,3,FALSE) -> ANALYST
A24: E102 | B24: SIMRAN | C24: DEVELOPER | D24: 52000 | E24: 6000 | F24: 4000 | G24: 5 | H24: CHANDIGARH
A25: E103 | B25: RAHUL | C25: EXECUTIVE | D25: 38000 | E25: 4000 | F25: 2500 | G25: 3 | H25: AMRITSAR
A26: E104 | B26: PRIYA | C26: ACCOUNTANT | D26: 47000 | E26: 5000 | F26: 3500 | G26: 6 | H26: LUDHIANA | K26: DESIGNATION
A27: E105 | B27: KABIR | C27: ANALYST | D27: 50000 | E27: 5500 | F27: 3000 | G27: 4 | H27: JALANDHAR | J27: E102
A28: E106 | B28: NEHA | C28: ASSISTANT | D28: 32000 | E28: 3000 | F28: 2000 | G28: 2 | H28: PATIALA
A29: E107 | B29: ARJUN | C29: MANAGER | D29: 60000 | E29: 7000 | F29: 5000 | G29: 10 | H29: DELHI
A30: E108 | B30: MEENA | C30: EXECUTIVE | D30: 41000 | E30: 4500 | F30: 2800 | G30: 5 | H30: CHANDIGARH

Sheet PARTA-VLOOKUP
A1: #MIX ASSIGNMENT | C1: PART-A : VLOOKUP
A2: DATA TABLE : | K2: #1
A3: EMP ID | B3: EMP NAME | C3: DEPARTMENT | D3: DESIGNATION | E3: BASIC SALARY | F3: HRA | G3: BONUS | H3: EXPERIENCE | I3: CITY | K3: LOOKUP-VALUE | L3: DEPARTMENT
A4: E101 | B4: AMAN | C4: HR | D4: MANAGER | E4: 45000 | F4: 5000 | G4: 3000 | H4: 8 | I4: DELHI | K4: E105 | L4: =VLOOKUP(K4,A3:I11,3,FALSE) -> IT
A5: E102 | B5: SIMRAN | C5: IT | D5: DEVELOPER | E5: 52000 | F5: 6000 | G5: 4000 | H5: 5 | I5: CHANDIGARH
A6: E103 | B6: RAHUL | C6: SALES | D6: EXECUTIVE | E6: 38000 | F6: 4000 | G6: 2500 | H6: 3 | I6: AMRITSAR | K6: #2
A7: E104 | B7: PRIYA | C7: FINANCE | D7: ACCOUNTANT | E7: 47000 | F7: 5000 | G7: 3500 | H7: 6 | I7: LUDHIANA | K7: LOOKUP-VALUE | L7: DESIGNATION
A8: E105 | B8: KABIR | C8: IT | D8: ANALYST | E8: 50000 | F8: 5500 | G8: 3000 | H8: 4 | I8: JALANDHAR | K8: E102 | L8: =VLOOKUP(K8,A3:I11,4,FALSE) -> DEVELOPER
A9: E106 | B9: NEHA | C9: HR | D9: ASSISTANT | E9: 32000 | F9: 3000 | G9: 2000 | H9: 2 | I9: PATIALA
A10: E107 | B10: ARJUN | C10: SALES | D10: MANAGER | E10: 60000 | F10: 7000 | G10: 5000 | H10: 10 | I10: DELHI | K10: #3
A11: E108 | B11: MEENA | C11: FINANCE | D11: EXECUTIVE | E11: 41000 | F11: 4500 | G11: 2800 | H11: 5 | I11: CHANDIGARH | K11: LOOKUP-VALUE | L11: BASIC SALARY
K12: E101 | L12: =VLOOKUP(K12,$A$3:$I$11,5,FALSE) -> 45000
K13: E102 | L13: =VLOOKUP(K13,$A$3:$I$11,5,FALSE) -> 52000
A14: #7=CHOOSE FUNCTION | K14: E103 | L14: =VLOOKUP(K14,$A$3:$I$11,5,FALSE) -> 38000
A15: {=CHOOSE({1,2},B3:B11,A3:A11)} -> EMP NAME | B15: EMP ID | K15: E104 | L15: =VLOOKUP(K15,$A$3:$I$11,5,FALSE) -> 47000
A16: AMAN | B16: E101 | K16: E105 | L16: =VLOOKUP(K16,$A$3:$I$11,5,FALSE) -> 50000
A17: SIMRAN | B17: E102 | K17: E106 | L17: =VLOOKUP(K17,$A$3:$I$11,5,FALSE) -> 32000
A18: RAHUL | B18: E103 | K18: E107 | L18: =VLOOKUP(K18,$A$3:$I$11,5,FALSE) -> 60000
A19: PRIYA | B19: E104 | K19: E108 | L19: =VLOOKUP(K19,$A$3:$I$11,5,FALSE) -> 41000
A20: KABIR | B20: E105
A21: NEHA | B21: E106 | L21: #4 | M21: #5 (MATCH FUNCTION) | N21: #6
A22: ARJUN | B22: E107 | K22: LOOKUP-VALUE | L22: NAME | M22: BONUS | N22: TOTAL SALARY
A23: MEENA | B23: E108 | K23: E101 | L23: {=VLOOKUP(K23,$A$3:$I$11,{2},FALSE)} -> AMAN | M23: =VLOOKUP(K23,$A$3:$I$11,MATCH(M22,A3:I3,0),FALSE) -> 3000 | N23: {=SUM(VLOOKUP(K23,$A$3:$I$11,{5,6,7},FALSE))} -> 53000
K24: E102 | L24: {=VLOOKUP(K24,$A$3:$I$11,{2},FALSE)} -> SIMRAN | M24: =VLOOKUP(K24,$A$3:$I$11,MATCH(M23,A4:I4,0),FALSE) -> 4000 | N24: {=SUM(VLOOKUP(K24,$A$3:$I$11,{5,6,7},FALSE))} -> 62000
K25: E103 | L25: {=VLOOKUP(K25,$A$3:$I$11,{2},FALSE)} -> RAHUL | M25: =VLOOKUP(K25,$A$3:$I$11,MATCH(M24,A5:I5,0),FALSE) -> 2500 | N25: {=SUM(VLOOKUP(K25,$A$3:$I$11,{5,6,7},FALSE))} -> 44500
A26: #8 | K26: E104 | L26: {=VLOOKUP(K26,$A$3:$I$11,{2},FALSE)} -> PRIYA | M26: =VLOOKUP(K26,$A$3:$I$11,MATCH(M25,A6:I6,0),FALSE) -> 3500 | N26: {=SUM(VLOOKUP(K26,$A$3:$I$11,{5,6,7},FALSE))} -> 55500
A27: LOOKUP-VALUE | B27: EXPERIENCE | K27: E105 | L27: {=VLOOKUP(K27,$A$3:$I$11,{2},FALSE)} -> KABIR | M27: =VLOOKUP(K27,$A$3:$I$11,MATCH(M26,A7:I7,0),FALSE) -> 3000 | N27: {=SUM(VLOOKUP(K27,$A$3:$I$11,{5,6,7},FALSE))} -> 58500
A28: E107 | B28: =VLOOKUP(A28,A3:I11,8,FALSE) -> 10 | K28: E106 | L28: {=VLOOKUP(K28,$A$3:$I$11,{2},FALSE)} -> NEHA | M28: =VLOOKUP(K28,$A$3:$I$11,MATCH(M27,A8:I8,0),FALSE) -> 2000 | N28: {=SUM(VLOOKUP(K28,$A$3:$I$11,{5,6,7},FALSE))} -> 37000
K29: E107 | L29: {=VLOOKUP(K29,$A$3:$I$11,{2},FALSE)} -> ARJUN | M29: =VLOOKUP(K29,$A$3:$I$11,MATCH(M28,A9:I9,0),FALSE) -> 5000 | N29: {=SUM(VLOOKUP(K29,$A$3:$I$11,{5,6,7},FALSE))} -> 72000
K30: E108 | L30: {=VLOOKUP(K30,$A$3:$I$11,{2},FALSE)} -> MEENA | M30: =VLOOKUP(K30,$A$3:$I$11,MATCH(M29,A10:I10,0),FALSE) -> 2800 | N30: {=SUM(VLOOKUP(K30,$A$3:$I$11,{5,6,7},FALSE))} -> 48300
A31: #9
A32: LOOKUP-VALUE | B32: CITY
A33: E104 | B33: =VLOOKUP(A33,A3:I11,9,FALSE) -> LUDHIANA
A36: #10
A37: LOOKUP-VALUE | B37: NAME
A38: E101 | B38: =IFERROR((VLOOKUP(A38,$A$3:$I$11,2,FALSE)),"NOT FOUND") -> AMAN
A39: E102 | B39: =IFERROR((VLOOKUP(A39,$A$3:$I$11,2,FALSE)),"NOT FOUND") -> SIMRAN
A40: E103 | B40: =IFERROR((VLOOKUP(A40,$A$3:$I$11,2,FALSE)),"NOT FOUND") -> RAHUL
A41: E104 | B41: =IFERROR((VLOOKUP(A41,$A$3:$I$11,2,FALSE)),"NOT FOUND") -> PRIYA
A42: E105 | B42: =IFERROR((VLOOKUP(A42,$A$3:$I$11,2,FALSE)),"NOT FOUND") -> KABIR
...

Sheet PARTB-HLOOKUP
C1: #PART B HLOOKUP
A2: DATA TABLE
A3: PRODUCT ID | B3: P101 | C3: P102 | D3: P103 | E3: P104 | F3: P105 | I3: #1
A4: PRODUCT NAME | B4: KEYBOARD | C4: MOUSE | D4: PRINTER | E4: SCANNER | F4: MONITOR | I4: LOOKUP-VALUE | J4: PRODUCT NAME
A5: PRICE | B5: 800 | C5: 500 | D5: 6500 | E5: 4500 | F5: 9000 | I5: P103 | J5: =HLOOKUP(I5,A3:F6,2,FALSE) -> PRINTER
A6: STOCK | B6: 25 | C6: 40 | D6: 10 | E6: 8 | F6: 15
I8: #2
I9: LOOKUP-VALUE | J9: PRICE
I10: P104 | J10: =HLOOKUP(I10,A3:F6,3,FALSE) -> 4500
I13: #3
I14: LOOKUP-VALUE | J14: STOCK
I15: P101 | J15: =HLOOKUP(I15,A3:F6,4,FALSE) -> 25
I17: #4 | J17: (MATCH)
I18: LOOKUP-VALUE | J18: PRODUCT NAME
I19: P101 | J19: =HLOOKUP(I19,A3:F6,MATCH(J18,A3:A6,0),FALSE) -> KEYBOARD
I21: #5
I22: LOOKUP-VALUE | J22: PRODUCT NAME
I23: P101 | J23: =IFERROR(HLOOKUP(I23,$A$3:$F$6,2,FALSE),"NOT FOUND") -> KEYBOARD
I24: P102 | J24: =IFERROR(HLOOKUP(I24,$A$3:$F$6,2,FALSE),"NOT FOUND") -> MOUSE
I25: P106 | J25: =IFERROR(HLOOKUP(I25,$A$3:$F$6,2,FALSE),"NOT FOUND") -> NOT FOUND

Sheet PARTC-XLOOKUP
A1: EMP ID | B1: EMP NAME | C1: DEPARTMENT | D1: DESIGNATION | E1: BASIC SALARY | F1: HRA | G1: BONUS | H1: EXPERIENCE | I1: CITY
A2: E101 | B2: AMAN | C2: HR | D2: MANAGER | E2: 45000 | F2: 5000 | G2: 3000 | H2: 8 | I2: DELHI | K2: LOOK-UP VALUE | L2: DEPARTMENT
A3: E102 | B3: SIMRAN | C3: IT | D3: DEVELOPER | E3: 52000 | F3: 6000 | G3: 4000 | H3: 5 | I3: CHANDIGARH | K3: E106 | L3: =_xlfn.XLOOKUP(K3,A1:A9,C1:C9,"NOT FOUND",0,1) -> HR
A4: E103 | B4: RAHUL | C4: SALES | D4: EXECUTIVE | E4: 38000 | F4: 4000 | G4: 2500 | H4: 3 | I4: AMRITSAR
A5: E104 | B5: PRIYA | C5: FINANCE | D5: ACCOUNTANT | E5: 47000 | F5: 5000 | G5: 3500 | H5: 6 | I5: LUDHIANA
A6: E105 | B6: KABIR | C6: IT | D6: ANALYST | E6: 50000 | F6: 5500 | G6: 3000 | H6: 4 | I6: JALANDHAR | K6: LOOK-UP VALUE | L6: CITY USING XLOOKUP | M6: CITY USING VLOOKUP
A7: E106 | B7: NEHA | C7: HR | D7: ASSISTANT | E7: 32000 | F7: 3000 | G7: 2000 | H7: 2 | I7: PATIALA | K7: E103 | L7: =_xlfn.XLOOKUP(K7,A1:A9,I1:I9,"NOT FOUND",0,1) -> AMRITSAR | M7: =VLOOKUP(K7,A1:I9,9,FALSE) -> AMRITSAR
A8: E107 | B8: ARJUN | C8: SALES | D8: MANAGER | E8: 60000 | F8: 7000 | G8: 5000 | H8: 10 | I8: DELHI
A9: E108 | B9: MEENA | C9: FINANCE | D9: EXECUTIVE | E9: 41000 | F9: 4500 | G9: 2800 | H9: 5 | I9: CHANDIGARH
K10: LOOK-UP VALUE | L10: BASIC SALARY
K11: E107 | L11: =_xlfn.XLOOKUP(K11,A1:A9,E1:E9,"RECORD NOT FOUND",0,1) -> 60000
K12: E111 | L12: =_xlfn.XLOOKUP(K12,A2:A10,E2:E10,"RECORD NOT FOUND",0,1) -> RECORD NOT FOUND
A14: PART-C : XLOOKUP
L15: (CHOOSE FUNC)
K16: LOOK-UP VALUE | L16: EMP NAME | M16: DEPARTMENT | N16: BASIC SALARY | O16: HRA
K17: E101 | L17: {=_xlfn.XLOOKUP(K17,$A$1:$A$9,CHOOSE({1,2,3,4},$B$1:$B$9,$C$1:$C$9,$E$1:$E$9,$F$1:$F$9),"DATA NOT FOUND",0,1)} -> AMAN | M17: HR | N17: 45000 | O17: 5000
K18: E102 | L18: {=_xlfn.XLOOKUP(K18,$A$1:$A$9,CHOOSE({1,2,3,4},$B$1:$B$9,$C$1:$C$9,$E$1:$E$9,$F$1:$F$9),"DATA NOT FOUND",0,1)} -> SIMRAN | M18: IT | N18: 52000 | O18: 6000
K19: E103 | L19: {=_xlfn.XLOOKUP(K19,$A$1:$A$9,CHOOSE({1,2,3,4},$B$1:$B$9,$C$1:$C$9,$E$1:$E$9,$F$1:$F$9),"DATA NOT FOUND",0,1)} -> RAHUL | M19: SALES | N19: 38000 | O19: 4000
K20: E104 | L20: {=_xlfn.XLOOKUP(K20,$A$1:$A$9,CHOOSE({1,2,3,4},$B$1:$B$9,$C$1:$C$9,$E$1:$E$9,$F$1:$F$9),"DATA NOT FOUND",0,1)} -> PRIYA | M20: FINANCE | N20: 47000 | O20: 5000
K21: E105 | L21: {=_xlfn.XLOOKUP(K21,$A$1:$A$9,CHOOSE({1,2,3,4},$B$1:$B$9,$C$1:$C$9,$E$1:$E$9,$F$1:$F$9),"DATA NOT FOUND",0,1)} -> KABIR | M21: IT | N21: 50000 | O21: 5500
K22: E106 | L22: {=_xlfn.XLOOKUP(K22,$A$1:$A$9,CHOOSE({1,2,3,4},$B$1:$B$9,$C$1:$C$9,$E$1:$E$9,$F$1:$F$9),"DATA NOT FOUND",0,1)} -> NEHA | M22: HR | N22: 32000 | O22: 3000
K23: E107 | L23: {=_xlfn.XLOOKUP(K23,$A$1:$A$9,CHOOSE({1,2,3,4},$B$1:$B$9,$C$1:$C$9,$E$1:$E$9,$F$1:$F$9),"DATA NOT FOUND",0,1)} -> ARJUN | M23: SALES | N23: 60000 | O23: 7000
K24: E108 | L24: {=_xlfn.XLOOKUP(K24,$A$1:$A$9,CHOOSE({1,2,3,4},$B$1:$B$9,$C$1:$C$9,$E$1:$E$9,$F$1:$F$9),"DATA NOT FOUND",0,1)} -> MEENA | M24: FINANCE | N24: 41000 | O24: 4500
K27: LOOK-UP VALUE | L27: EMP NAME
K28: E101 | L28: =_xlfn.XLOOKUP(K28,$A$1:$A$9,$B$1:$B$9,"DATA NOT FOUND",0,1) -> AMAN
K29: E102 | L29: =_xlfn.XLOOKUP(K29,$A$1:$A$9,$B$1:$B$9,"DATA NOT FOUND",0,1) -> SIMRAN
K30: E103 | L30: =_xlfn.XLOOKUP(K30,$A$1:$A$9,$B$1:$B$9,"DATA NOT FOUND",0,1) -> RAHUL
K31: E104 | L31: =_xlfn.XLOOKUP(K31,$A$1:$A$9,$B$1:$B$9,"DATA NOT FOUND",0,1) -> PRIYA
K32: E105 | L32: =_xlfn.XLOOKUP(K32,$A$1:$A$9,$B$1:$B$9,"DATA NOT FOUND",0,1) -> KABIR
K33: E106 | L33: =_xlfn.XLOOKUP(K33,$A$1:$A$9,$B$1:$B$9,"DATA NOT FOUND",0,1) -> NEHA
K34: E107 | L34: =_xlfn.XLOOKUP(K34,$A$1:$A$9,$B$1:$B$9,"DATA NOT FOUND",0,1) -> ARJUN
K35: E108 | L35: =_xlfn.XLOOKUP(K35,$A$1:$A$9,$B$1:$B$9,"DATA NOT FOUND",0,1) -> MEENA
